<mujoco model="rover">
  <option iterations="50" timestep="0.001" solver="PGS" gravity="0 0 -9.81" />

  <compiler angle="radian" meshdir="meshes" eulerseq="zyx" autolimits="true" />

  <default>
    <joint limited="true" damping="0.01" armature="0.01" frictionloss="0.01" />
    <geom condim="4" contype="1" conaffinity="15" friction="0.9 0.2 0.2" solref="0.001 2" />
    <motor ctrllimited="true" />
    <equality solref="0.001 2" />
    <default class="visualgeom">
      <geom material="visualgeom" condim="1" contype="0" conaffinity="0" />
    </default>
  </default>

  <worldbody>
    <light directional="true" diffuse="0.4 0.4 0.4" specular="0.1 0.1 0.1" pos="0 0 5.0" dir="0 0 -1" castshadow="false" />
    <light directional="true" diffuse="0.6 0.6 0.6" specular="0.2 0.2 0.2" pos="0 0 4" dir="0 0 -1" />
    <geom name="ground" type="plane" pos="0 0 0" size="100 100 0.001" quat="1 0 0 0" material="matplane" condim="3" conaffinity="15" />
    <camera name="fixed" pos="0 -3.0 0.7" xyaxes="1 0 0 0 0 1" />
    <camera name="track" mode="trackcom" pos="0 -3.0 0.7" xyaxes="1 0 0 0 0 1" />
    <body name="root" pos="0 0 0.2" quat="1 0 0 0">
      <freejoint name="root" />
      <site name="imu" size="0.01" pos="0 0 0" />
      <geom size="0.0005 0.0005 0.0005" pos="0 0 0.05" type="box" contype="1" conaffinity="0" density="0" group="1" class="visualgeom" />
      <geom type="box" rgba="" size="0.0005 0.0005 0.0005" pos="0 0 0.05" />
      <geom size="0.15 0.125 0.025" pos="0 0 -0.025" type="box" contype="1" conaffinity="0" density="0" group="1" class="visualgeom" />
      <geom type="box" rgba="" size="0.15 0.125 0.025" pos="0 0 -0.025" />
      <geom size="0.0175 0.0925 0.0125" pos="0.2 0 -0.0125" type="box" contype="1" conaffinity="0" density="0" group="1" class="visualgeom" />
      <geom type="box" rgba="" size="0.0175 0.0925 0.0125" pos="0.2 0 -0.0125" />
      <body name="left_bogie_front_wheel" pos="0.25 0.2 -0.2" quat="0.707107 0.707107 0 0">
        <inertial pos="0 0 0" quat="0.5 0.5 -0.5 0.5" mass="0.2" diaginertia="0.000580625 0.000384063 0.000384063" />
        <joint name="left_bogie_front_axle" pos="0 0 0" axis="0 0 -1"  range="-1.0 1.0"/>
        <geom size="0.0575 0.0375" type="cylinder" rgba="0 0 0 1" contype="1" conaffinity="0" density="0" group="1" class="visualgeom" />
       <geom type="cylinder" size="0.05 0.02" rgba="0 0 0 1"/>

      </body>
      <body name="left_bogie_rear_wheel" pos="0.05 0.2 -0.2" quat="0.707107 0.707107 0 0">
        <inertial pos="0 0 0" quat="0.5 0.5 -0.5 0.5" mass="0.2" diaginertia="0.000580625 0.000384063 0.000384063" />
        <joint name="left_bogie_rear_axle" pos="0 0 0" axis="0 0 -1"  range="-1.0 1.0"/>
        <geom size="0.0575 0.0375" type="cylinder" rgba="0 0 0 1" contype="1" conaffinity="0" density="0" group="1" class="visualgeom" />
       <geom type="cylinder" size="0.05 0.02" rgba="0 0 0 1"/>

      </body>
      <body name="left_rocker_rear_wheel" pos="-0.175 0.2 -0.2" quat="0.707107 0.707107 0 0">
        <inertial pos="0 0 0" quat="0.5 0.5 -0.5 0.5" mass="0.2" diaginertia="0.000580625 0.000384063 0.000384063" />
        <joint name="left_rocker_rear_axle" pos="0 0 0" axis="0 0 -1"  range="-1.0 1.0"/>
        <geom size="0.0575 0.0375" type="cylinder" rgba="0 0 0 1" contype="1" conaffinity="0" density="0" group="1" class="visualgeom" />
       <geom type="cylinder" size="0.05 0.02" rgba="0 0 0 1"/>

      </body>
      <body name="right_bogie_front_wheel" pos="0.25 -0.2 -0.2" quat="0.707107 0.707107 0 0">
        <inertial pos="0 0 0" quat="0.5 0.5 -0.5 0.5" mass="0.2" diaginertia="0.000580625 0.000384063 0.000384063" />
        <joint name="right_bogie_front_axle" pos="0 0 0" axis="0 0 -1"  range="-1.0 1.0"/>
        <geom size="0.0575 0.0375" type="cylinder" rgba="0 0 0 1" contype="1" conaffinity="0" density="0" group="1" class="visualgeom" />
       <geom type="cylinder" size="0.05 0.02" rgba="0 0 0 1"/>

      </body>
      <body name="right_bogie_rear_wheel" pos="0.05 -0.2 -0.2" quat="0.707107 0.707107 0 0">
        <inertial pos="0 0 0" quat="0.5 0.5 -0.5 0.5" mass="0.2" diaginertia="0.000580625 0.000384063 0.000384063" />
        <joint name="right_bogie_rear_axle" pos="0 0 0" axis="0 0 -1"  range="-1.0 1.0"/>
        <geom size="0.0575 0.0375" type="cylinder" rgba="0 0 0 1" contype="1" conaffinity="0" density="0" group="1" class="visualgeom" />
       <geom type="cylinder" size="0.05 0.02" rgba="0 0 0 1"/>

      </body>
      <body name="right_rocker_rear_wheel" pos="-0.175 -0.2 -0.2" quat="0.707107 0.707107 0 0">
        <inertial pos="0 0 0" quat="0.5 0.5 -0.5 0.5" mass="0.2" diaginertia="0.000580625 0.000384063 0.000384063" />
        <joint name="right_rocker_rear_axle" pos="0 0 0" axis="0 0 -1"  range="-1.0 1.0"/>
        <geom size="0.0575 0.0375" type="cylinder" rgba="0 0 0 1" contype="1" conaffinity="0" density="0" group="1" class="visualgeom" />
       <geom type="cylinder" size="0.05 0.02" rgba="0 0 0 1"/>

      </body>
    </body>
  </worldbody>

  <asset>
    <texture name="texplane" type="2d" builtin="checker" rgb1=".0 .0 .0" rgb2=".8 .8 .8" width="100" height="100" />
    <material name="matplane" reflectance="0." texture="texplane" texrepeat="1 1" texuniform="true" />
    <material name="visualgeom" rgba="0.5 0.9 0.2 1" />
  </asset>

  <actuator>
    <motor name="left_bogie_front_axle" joint="left_bogie_front_axle" ctrllimited="true" ctrlrange="-5.12766 5.12766" gear="1" />
    <motor name="left_bogie_rear_axle" joint="left_bogie_rear_axle" ctrllimited="true" ctrlrange="-5.12766 5.12766" gear="1" />
    <motor name="left_rocker_rear_axle" joint="left_rocker_rear_axle" ctrllimited="true" ctrlrange="-5.12766 5.12766" gear="1" />
    <motor name="right_bogie_front_axle" joint="right_bogie_front_axle" ctrllimited="true" ctrlrange="-5.12766 5.12766" gear="1" />
    <motor name="right_bogie_rear_axle" joint="right_bogie_rear_axle" ctrllimited="true" ctrlrange="-5.12766 5.12766" gear="1" />
    <motor name="right_rocker_rear_axle" joint="right_rocker_rear_axle" ctrllimited="true" ctrlrange="-5.12766 5.12766" gear="1" />
  </actuator>

  <sensor>
    <actuatorpos name="left_bogie_front_axle_p" actuator="left_bogie_front_axle" />
    <actuatorvel name="left_bogie_front_axle_v" actuator="left_bogie_front_axle" />
    <actuatorfrc name="left_bogie_front_axle_f" actuator="left_bogie_front_axle" noise="0.001" />
    <actuatorpos name="left_bogie_rear_axle_p" actuator="left_bogie_rear_axle" />
    <actuatorvel name="left_bogie_rear_axle_v" actuator="left_bogie_rear_axle" />
    <actuatorfrc name="left_bogie_rear_axle_f" actuator="left_bogie_rear_axle" noise="0.001" />
    <actuatorpos name="left_rocker_rear_axle_p" actuator="left_rocker_rear_axle" />
    <actuatorvel name="left_rocker_rear_axle_v" actuator="left_rocker_rear_axle" />
    <actuatorfrc name="left_rocker_rear_axle_f" actuator="left_rocker_rear_axle" noise="0.001" />
    <actuatorpos name="right_bogie_front_axle_p" actuator="right_bogie_front_axle" />
    <actuatorvel name="right_bogie_front_axle_v" actuator="right_bogie_front_axle" />
    <actuatorfrc name="right_bogie_front_axle_f" actuator="right_bogie_front_axle" noise="0.001" />
    <actuatorpos name="right_bogie_rear_axle_p" actuator="right_bogie_rear_axle" />
    <actuatorvel name="right_bogie_rear_axle_v" actuator="right_bogie_rear_axle" />
    <actuatorfrc name="right_bogie_rear_axle_f" actuator="right_bogie_rear_axle" noise="0.001" />
    <actuatorpos name="right_rocker_rear_axle_p" actuator="right_rocker_rear_axle" />
    <actuatorvel name="right_rocker_rear_axle_v" actuator="right_rocker_rear_axle" />
    <actuatorfrc name="right_rocker_rear_axle_f" actuator="right_rocker_rear_axle" noise="0.001" />
    <framequat name="orientation" objtype="site" noise="0.001" objname="imu" />
    <gyro name="angular-velocity" site="imu" noise="0.005" cutoff="34.9" />
  </sensor>
</mujoco>