<?xml version="1.0" ?>
<!-- =================================================================================== -->
<!-- |    This document was autogenerated by xacro from rover.urdf.xacro               | -->
<!-- |    EDITING THIS FILE BY HAND IS NOT RECOMMENDED                                 | -->
<!-- =================================================================================== -->
<robot name="rover">
  <material name="body_mat">
    <color rgba="0.5 0.5 0.5 1"/>
  </material>
  <material name="tire_mat">
    <color rgba="0 0 0 1"/>
  </material>
  <!-- base_link must have geometry so that its axes can be displayed in
       rviz. -->
  <link name="base_link">
    <visual>
      <geometry>
        <box size="0.05 0.05 0.01"/>
      </geometry>
      <material name="body_mat"/>
    </visual>
  </link>
  <gazebo reference="base_link">
    <material>Gazebo/Green</material>
  </gazebo>
  <joint name="imu_joint" type="fixed">
    <axis xyz="1 0 0"/>
    <origin xyz="0 0 0.05"/>
    <parent link="base_link"/>
    <child link="imu_link"/>
  </joint>
  <link name="imu_link">
    <inertial>
      <mass value="0.001"/>
      <origin rpy="0 0 0" xyz="0 0 0"/>
      <inertia ixx="0.0001" ixy="0" ixz="0" iyy="0.000001" iyz="0" izz="0.0001"/>
    </inertial>
    <visual>
      <origin rpy="0 0 0" xyz="0 0 0"/>
      <geometry>
        <box size="0.001 0.001 0.001"/>
      </geometry>
    </visual>
    <collision>
      <origin rpy="0 0 0" xyz="0 0 0"/>
      <geometry>
        <box size=".001 .001 .001"/>
      </geometry>
    </collision>
  </link>
  <!-- body -->
  <link name="body">
    <visual>
      <origin xyz="0 0 -0.025"/>
      <geometry>
        <box size="0.3 0.25 0.05"/>
      </geometry>
      <material name="body_mat"/>
    </visual>
    <collision>
      <origin xyz="0 0 -0.025"/>
      <geometry>
        <box size="0.3 0.25 0.05"/>
      </geometry>
    </collision>
    <inertial>
      <origin xyz="0 0 -0.025"/>
      <mass value="3.0"/>
      <inertia ixx="0.01625" ixy="0" ixz="0" iyy="0.023124999999999996" iyz="0" izz="0.038125"/>
    </inertial>
  </link>
  <gazebo reference="body">
    <material>Gazebo/Grey</material>
  </gazebo>
  <joint name="base_link_to_chasis" type="fixed">
    <parent link="base_link"/>
    <child link="body"/>
  </joint>
  <joint name="left_bogie_front_axle" type="continuous">
    <parent link="base_link"/>
    <child link="left_bogie_front_wheel"/>
    <origin rpy="1.57079633 0 0" xyz="0.25                    0.2                    -0.2"/>
    <axis xyz="0 0 -1"/>
    <limit effort="5.12766" velocity="244.8696"/>
  </joint>
  <transmission name="left_bogie_front_axle_trans">
    <type>transmission_interface/SimpleTransmission</type>
    <joint name="left_bogie_front_axle">
      <hardwareInterface>VelocityJointInterface</hardwareInterface>
    </joint>
    <actuator name="left_bogie_front_axle_act">
      <hardwareInterface>VelocityJointInterface</hardwareInterface>
      <mechanicalReduction>1</mechanicalReduction>
    </actuator>
  </transmission>
  <link name="left_bogie_front_wheel">
    <visual>
      <origin xyz="0 0 0"/>
      <geometry>
        <cylinder length="0.075" radius="0.0575"/>
      </geometry>
      <material name="tire_mat"/>
    </visual>
    <collision>
      <origin xyz="0 0 0"/>
      <geometry>
        <cylinder length="0.075" radius="0.0575"/>
      </geometry>
    </collision>
    <inertial>
      <mass value="0.2"/>
      <inertia ixx="0.0003840625" ixy="0" ixz="0" iyy="0.0003840625" iyz="0" izz="0.0005806250000000001"/>
    </inertial>
  </link>
  <gazebo reference="left_bogie_front_wheel">
    <material>Gazebo/Black</material>
  </gazebo>
  <joint name="left_bogie_rear_axle" type="continuous">
    <parent link="base_link"/>
    <child link="left_bogie_rear_wheel"/>
    <origin rpy="1.57079633 0 0" xyz="0.04999999999999999                    0.2                    -0.2"/>
    <axis xyz="0 0 -1"/>
    <limit effort="5.12766" velocity="244.8696"/>
  </joint>
  <transmission name="left_bogie_rear_axle_trans">
    <type>transmission_interface/SimpleTransmission</type>
    <joint name="left_bogie_rear_axle">
      <hardwareInterface>VelocityJointInterface</hardwareInterface>
    </joint>
    <actuator name="left_bogie_rear_axle_act">
      <hardwareInterface>VelocityJointInterface</hardwareInterface>
      <mechanicalReduction>1</mechanicalReduction>
    </actuator>
  </transmission>
  <link name="left_bogie_rear_wheel">
    <visual>
      <origin xyz="0 0 0"/>
      <geometry>
        <cylinder length="0.075" radius="0.0575"/>
      </geometry>
      <material name="tire_mat"/>
    </visual>
    <collision>
      <origin xyz="0 0 0"/>
      <geometry>
        <cylinder length="0.075" radius="0.0575"/>
      </geometry>
    </collision>
    <inertial>
      <mass value="0.2"/>
      <inertia ixx="0.0003840625" ixy="0" ixz="0" iyy="0.0003840625" iyz="0" izz="0.0005806250000000001"/>
    </inertial>
  </link>
  <gazebo reference="left_bogie_rear_wheel">
    <material>Gazebo/Black</material>
  </gazebo>
  <joint name="left_rocker_rear_axle" type="continuous">
    <parent link="base_link"/>
    <child link="left_rocker_rear_wheel"/>
    <origin rpy="1.57079633 0 0" xyz="-0.175                    0.2                    -0.2"/>
    <axis xyz="0 0 -1"/>
    <limit effort="5.12766" velocity="244.8696"/>
  </joint>
  <transmission name="left_rocker_rear_axle_trans">
    <type>transmission_interface/SimpleTransmission</type>
    <joint name="left_rocker_rear_axle">
      <hardwareInterface>VelocityJointInterface</hardwareInterface>
    </joint>
    <actuator name="left_rocker_rear_axle_act">
      <hardwareInterface>VelocityJointInterface</hardwareInterface>
      <mechanicalReduction>1</mechanicalReduction>
    </actuator>
  </transmission>
  <link name="left_rocker_rear_wheel">
    <visual>
      <origin xyz="0 0 0"/>
      <geometry>
        <cylinder length="0.075" radius="0.0575"/>
      </geometry>
      <material name="tire_mat"/>
    </visual>
    <collision>
      <origin xyz="0 0 0"/>
      <geometry>
        <cylinder length="0.075" radius="0.0575"/>
      </geometry>
    </collision>
    <inertial>
      <mass value="0.2"/>
      <inertia ixx="0.0003840625" ixy="0" ixz="0" iyy="0.0003840625" iyz="0" izz="0.0005806250000000001"/>
    </inertial>
  </link>
  <gazebo reference="left_rocker_rear_wheel">
    <material>Gazebo/Black</material>
  </gazebo>
  <joint name="right_bogie_front_axle" type="continuous">
    <parent link="base_link"/>
    <child link="right_bogie_front_wheel"/>
    <origin rpy="1.57079633 0 0" xyz="0.25                    -0.2                    -0.2"/>
    <axis xyz="0 0 -1"/>
    <limit effort="5.12766" velocity="244.8696"/>
  </joint>
  <transmission name="right_bogie_front_axle_trans">
    <type>transmission_interface/SimpleTransmission</type>
    <joint name="right_bogie_front_axle">
      <hardwareInterface>VelocityJointInterface</hardwareInterface>
    </joint>
    <actuator name="right_bogie_front_axle_act">
      <hardwareInterface>VelocityJointInterface</hardwareInterface>
      <mechanicalReduction>1</mechanicalReduction>
    </actuator>
  </transmission>
  <link name="right_bogie_front_wheel">
    <visual>
      <origin xyz="0 0 0"/>
      <geometry>
        <cylinder length="0.075" radius="0.0575"/>
      </geometry>
      <material name="tire_mat"/>
    </visual>
    <collision>
      <origin xyz="0 0 0"/>
      <geometry>
        <cylinder length="0.075" radius="0.0575"/>
      </geometry>
    </collision>
    <inertial>
      <mass value="0.2"/>
      <inertia ixx="0.0003840625" ixy="0" ixz="0" iyy="0.0003840625" iyz="0" izz="0.0005806250000000001"/>
    </inertial>
  </link>
  <gazebo reference="right_bogie_front_wheel">
    <material>Gazebo/Black</material>
  </gazebo>
  <joint name="right_bogie_rear_axle" type="continuous">
    <parent link="base_link"/>
    <child link="right_bogie_rear_wheel"/>
    <origin rpy="1.57079633 0 0" xyz="0.04999999999999999                    -0.2                    -0.2"/>
    <axis xyz="0 0 -1"/>
    <limit effort="5.12766" velocity="244.8696"/>
  </joint>
  <transmission name="right_bogie_rear_axle_trans">
    <type>transmission_interface/SimpleTransmission</type>
    <joint name="right_bogie_rear_axle">
      <hardwareInterface>VelocityJointInterface</hardwareInterface>
    </joint>
    <actuator name="right_bogie_rear_axle_act">
      <hardwareInterface>VelocityJointInterface</hardwareInterface>
      <mechanicalReduction>1</mechanicalReduction>
    </actuator>
  </transmission>
  <link name="right_bogie_rear_wheel">
    <visual>
      <origin xyz="0 0 0"/>
      <geometry>
        <cylinder length="0.075" radius="0.0575"/>
      </geometry>
      <material name="tire_mat"/>
    </visual>
    <collision>
      <origin xyz="0 0 0"/>
      <geometry>
        <cylinder length="0.075" radius="0.0575"/>
      </geometry>
    </collision>
    <inertial>
      <mass value="0.2"/>
      <inertia ixx="0.0003840625" ixy="0" ixz="0" iyy="0.0003840625" iyz="0" izz="0.0005806250000000001"/>
    </inertial>
  </link>
  <gazebo reference="right_bogie_rear_wheel">
    <material>Gazebo/Black</material>
  </gazebo>
  <joint name="right_rocker_rear_axle" type="continuous">
    <parent link="base_link"/>
    <child link="right_rocker_rear_wheel"/>
    <origin rpy="1.57079633 0 0" xyz="-0.175                    -0.2                    -0.2"/>
    <axis xyz="0 0 -1"/>
    <limit effort="5.12766" velocity="244.8696"/>
  </joint>
  <transmission name="right_rocker_rear_axle_trans">
    <type>transmission_interface/SimpleTransmission</type>
    <joint name="right_rocker_rear_axle">
      <hardwareInterface>VelocityJointInterface</hardwareInterface>
    </joint>
    <actuator name="right_rocker_rear_axle_act">
      <hardwareInterface>VelocityJointInterface</hardwareInterface>
      <mechanicalReduction>1</mechanicalReduction>
    </actuator>
  </transmission>
  <link name="right_rocker_rear_wheel">
    <visual>
      <origin xyz="0 0 0"/>
      <geometry>
        <cylinder length="0.075" radius="0.0575"/>
      </geometry>
      <material name="tire_mat"/>
    </visual>
    <collision>
      <origin xyz="0 0 0"/>
      <geometry>
        <cylinder length="0.075" radius="0.0575"/>
      </geometry>
    </collision>
    <inertial>
      <mass value="0.2"/>
      <inertia ixx="0.0003840625" ixy="0" ixz="0" iyy="0.0003840625" iyz="0" izz="0.0005806250000000001"/>
    </inertial>
  </link>
  <gazebo reference="right_rocker_rear_wheel">
    <material>Gazebo/Black</material>
  </gazebo>
  <gazebo>
    <plugin filename="libgazebo_ros_control.so" name="gazebo_ros_control"/>
  </gazebo>
  <joint name="camera_joint" type="fixed">
    <origin rpy="0 0 0" xyz="0.2 0.0 -0.0125"/>
    <parent link="base_link"/>
    <child link="camera_link"/>
  </joint>
  <link name="camera_link">
    <inertial>
      <mass value="0.200"/>
      <origin rpy="0 0 0" xyz="0 0 0"/>
      <inertia ixx="5.8083e-4" ixy="0" ixz="0" iyy="3.0833e-5" iyz="0" izz="5.9083e-4"/>
    </inertial>
    <visual>
      <origin rpy="0 0 0" xyz="0 0 0"/>
      <geometry>
        <mesh filename="package://hector_sensors_description/meshes/asus_camera/asus_camera_simple.dae"/>
      </geometry>
    </visual>
    <collision>
      <origin rpy="0 0 0" xyz="0 0 0"/>
      <geometry>
        <box size="0.035 0.185 0.025"/>
      </geometry>
    </collision>
  </link>
  <joint name="camera_depth_joint" type="fixed">
    <origin rpy="0 0 0" xyz="0.0 0.049 0.0"/>
    <parent link="camera_link"/>
    <child link="camera_depth_frame"/>
  </joint>
  <link name="camera_depth_frame"/>
  <joint name="camera_depth_optical_joint" type="fixed">
    <origin rpy="-1.5707963267948966 0.0 -1.5707963267948966" xyz="0 0 0"/>
    <parent link="camera_depth_frame"/>
    <child link="camera_depth_optical_frame"/>
  </joint>
  <link name="camera_depth_optical_frame"/>
  <joint name="camera_rgb_joint" type="fixed">
    <origin rpy="0 0 0" xyz="0.0 0.022 0.0"/>
    <parent link="camera_link"/>
    <child link="camera_rgb_frame"/>
  </joint>
  <link name="camera_rgb_frame"/>
  <joint name="camera_rgb_optical_joint" type="fixed">
    <origin rpy="-1.5707963267948966 0.0 -1.5707963267948966" xyz="0 0 0"/>
    <parent link="camera_rgb_frame"/>
    <child link="camera_rgb_optical_frame"/>
  </joint>
  <link name="camera_rgb_optical_frame"/>
  <gazebo reference="camera_depth_frame">
    <sensor name="camera" type="depth">
      <update_rate>20</update_rate>
      <camera>
        <horizontal_fov>1.0960667702524387</horizontal_fov>
        <image>
          <format>R8G8B8</format>
          <width>640</width>
          <height>480</height>
        </image>
        <clip>
          <near>0.5</near>
          <far>9</far>
        </clip>
      </camera>
      <plugin filename="libgazebo_ros_openni_kinect.so" name="camera_camera_controller">
        <cameraName>camera</cameraName>
        <imageTopicName>camera/rgb/image_raw</imageTopicName>
        <cameraInfoTopicName>camera/rgb/camera_info</cameraInfoTopicName>
        <depthImageTopicName>camera/depth/image_raw</depthImageTopicName>
        <depthImageCameraInfoTopicName>camera/depth/camera_info</depthImageCameraInfoTopicName>
        <pointCloudTopicName>camera/depth/points</pointCloudTopicName>
        <frameName>camera_depth_optical_frame</frameName>
        <pointCloudCutoff>0.3</pointCloudCutoff>
        <pointCloudCutoffMax>5.0</pointCloudCutoffMax>
      </plugin>
    </sensor>
  </gazebo>
  <!-- IMU sensor-->
  <gazebo>
    <plugin filename="libhector_gazebo_ros_imu.so" name="imu_sim" type="imu">
      <alwaysOn>true</alwaysOn>
      <topicName>imu/data</topicName>
      <updateRate>100.0</updateRate>
      <serviceName>imu_service</serviceName>
      <bodyName>imu_link</bodyName>
      <frameId>imu_link</frameId>
      <accelOffset>0.1 0.1 0.1</accelOffset>
      <accelDrift>0.0 0.0 0.0</accelDrift>
      <accelDriftFrequency>0.0 0.0 0.0</accelDriftFrequency>
      <accelGaussianNoise>0.35 0.35 0.3</accelGaussianNoise>
      <rateOffset>0.0 0.0 0.0</rateOffset>
      <rateDrift>0.01 0.01 0.01</rateDrift>
      <rateDriftFrequency>0.0 0.0 0.0</rateDriftFrequency>
      <rateGaussianNoise>0.05 0.05 0.015</rateGaussianNoise>
      <headingOffset>0.0 0.0 0.0</headingOffset>
      <headingDrift>0.0 0.0 0.0</headingDrift>
      <headingDriftFrequency>0.0 0.0 0.0</headingDriftFrequency>
      <headingGaussianNoise>0.05 0.05 0.05</headingGaussianNoise>
    </plugin>
  </gazebo>
  <plugin filename="libhector_gazebo_ros_magnetic.so" name="magnetic_sim">
    <alwaysOn>true</alwaysOn>
    <topicName>magnetic/data</topicName>
    <updateRate>100.0</updateRate>
    <bodyName>imu_link</bodyName>
    <frameId>imu_link</frameId>
    <magnitude>46967.9</magnitude>
    <declination>-2.3865</declination>
    <inclination>-61.7292</inclination>
    <offset>0.0 0.0 0.0</offset>
    <drift>0.0 0.0 0.0</drift>
    <gaussianNoise>100.0 100.0 100.0</gaussianNoise>
  </plugin>
  <plugin filename="libhector_gazebo_ros_gps.so" name="gps_sim">
    <updateRate>1.0</updateRate>
    <bodyName>imu_link</bodyName>
    <frameId>imu_link</frameId>
    <topicName>gps/fix</topicName>
    <velocityTopicName>gps/vel</velocityTopicName>
    <referenceLatitude>46.518125</referenceLatitude>
    <referenceLongitude>6.565539</referenceLongitude>
    <drift>0 0 0</drift>
    <gaussianNoise>0.0 0.0 0.0</gaussianNoise>
    <velocityDrift>0 0 0</velocityDrift>
    <velocityGaussianNoise>0.05 0.05 0.05</velocityGaussianNoise>
  </plugin>
</robot>

