<mujoco model="rover">
  <!-- ===================== OPTIONS ===================== -->
  <option iterations="50" timestep="0.001" solver="PGS" gravity="0 0 -1.62" />

  <compiler angle="radian" meshdir="meshes" eulerseq="zyx" autolimits="true" />

  <default>
    <joint limited="true" damping="0.01" armature="0.01" frictionloss="0.01" />
    <geom condim="4" contype="1" conaffinity="15" friction="1.5 0.3 0.3" solref="0.001 2" />
    <motor ctrllimited="true" />
    <equality solref="0.001 2" />
    <default class="visualgeom">
      <geom material="visualgeom" condim="1" contype="0" conaffinity="0" />
    </default>
  </default>

  <asset>
    <hfield name="terrain_hf" file="/Users/denismbeyakola/Desktop/space_robotics/terrain.png" size="10 10 0.5 0.30" />
    <material name="visualgeom" rgba="0.5 0.9 0.2 1" />
  </asset>

  <worldbody>
    <geom name="ground" type="hfield" hfield="terrain_hf" pos="0 0 0" contype="1" conaffinity="15" />
    <light directional="true" diffuse="0.4 0.4 0.4" specular="0.1 0.1 0.1" pos="0 0 5.0" dir="0 0 -1" castshadow="false" />
    <light directional="true" diffuse="0.6 0.6 0.6" specular="0.2 0.2 0.2" pos="0 0 4" dir="0 0 -1" />

    <camera name="fixed" pos="0 -3.0 0.7" xyaxes="1 0 0 0 0 1" />
    <camera name="track" mode="trackcom" pos="0 -3.0 0.7" xyaxes="1 0 0 0 0 1" />

    <!-- ===================== ROVER BODY ===================== -->
    <body name="root" pos="0 0 0.18" quat="1 0 0 0">
      <freejoint name="root" />
      <inertial pos="0 0 0" mass="7.0" diaginertia="0.1 0.1 0.1" />
      <site name="imu" size="0.01" pos="0 0 0" />
      <geom size="0.15 0.125 0.025" pos="0 0 -0.025" type="box" contype="1" conaffinity="0" density="500" group="1" class="visualgeom" />

      <!-- ===================== WHEELS ===================== -->
      <body name="left_bogie_front_wheel" pos="0.25 0.2 -0.2" quat="0.707107 0.707107 0 0">
        <inertial pos="0 0 0" mass="0.3" diaginertia="0.0008 0.0005 0.0005" />
        <joint name="left_bogie_front_axle" axis="0 0 1" type="hinge" limited="false"/>
        <geom size="0.0575 0.0375" type="cylinder" rgba="0 0 0 1" contype="1" conaffinity="0" density="100" friction="2 0.5 0.5"/>
      </body>

      <body name="left_bogie_rear_wheel" pos="0.05 0.2 -0.2" quat="0.707107 0.707107 0 0">
        <inertial pos="0 0 0" mass="0.3" diaginertia="0.0008 0.0005 0.0005" />
        <joint name="left_bogie_rear_axle" axis="0 0 1" type="hinge" limited="false"/>
        <geom size="0.0575 0.0375" type="cylinder" rgba="0 0 0 1" contype="1" conaffinity="0" density="100" friction="2 0.5 0.5"/>
      </body>

      <body name="left_rocker_rear_wheel" pos="-0.175 0.2 -0.2" quat="0.707107 0.707107 0 0">
        <inertial pos="0 0 0" mass="0.3" diaginertia="0.0008 0.0005 0.0005" />
        <joint name="left_rocker_rear_axle" axis="0 0 1" type="hinge" limited="false"/>
        <geom size="0.0575 0.0375" type="cylinder" rgba="0 0 0 1" contype="1" conaffinity="0" density="100" friction="2 0.5 0.5"/>
      </body>

      <body name="right_bogie_front_wheel" pos="0.25 -0.2 -0.2" quat="0.707107 0.707107 0 0">
        <inertial pos="0 0 0" mass="0.3" diaginertia="0.0008 0.0005 0.0005" />
        <joint name="right_bogie_front_axle" axis="0 0 1" type="hinge" limited="false"/>
        <geom size="0.0575 0.0375" type="cylinder" rgba="0 0 0 1" contype="1" conaffinity="0" density="100" friction="2 0.5 0.5"/>
      </body>

      <body name="right_bogie_rear_wheel" pos="0.05 -0.2 -0.2" quat="0.707107 0.707107 0 0">
        <inertial pos="0 0 0" mass="0.3" diaginertia="0.0008 0.0005 0.0005" />
        <joint name="right_bogie_rear_axle" axis="0 0 1" type="hinge" limited="false"/>
        <geom size="0.0575 0.0375" type="cylinder" rgba="0 0 0 1" contype="1" conaffinity="0" density="100" friction="2 0.5 0.5"/>
      </body>

      <body name="right_rocker_rear_wheel" pos="-0.175 -0.2 -0.2" quat="0.707107 0.707107 0 0">
        <inertial pos="0 0 0" mass="0.3" diaginertia="0.0008 0.0005 0.0005" />
        <joint name="right_rocker_rear_axle" axis="0 0 1" type="hinge" limited="false"/>
        <geom size="0.0575 0.0375" type="cylinder" rgba="0 0 0 1" contype="1" conaffinity="0" density="100" friction="2 0.5 0.5"/>
      </body>

      <!-- Mast for cameras -->
      <body name="camera_mast" pos="0 0 0.15">
        <geom name="mast_geom" type="cylinder" size="0.02 0.15" rgba="0.6 0.6 0.6 1" />
        <body name="sensor_mount" pos="0 0 0.3">
          <camera name="camera_left" pos="0 0.05 0" xyaxes="1 0 0 0 0 1" />
          <geom name="camera_left_geom" type="box" size="0.02 0.02 0.02" pos="0 0.05 0" rgba="0 0 1 1"/>
          <camera name="camera_right" pos="0 -0.05 0" xyaxes="1 0 0 0 0 1" />
          <geom name="camera_right_geom" type="box" size="0.02 0.02 0.02" pos="0 -0.05 0" rgba="1 0 0 1"/>
          <site name="depth_left_site" pos="0 0.05 0" size="0.01"/>
          <site name="depth_right_site" pos="0 -0.05 0" size="0.01"/>
        </body>
      </body>
    </body>
  </worldbody>

  <!-- ===================== ACTUATORS ===================== -->
  <actuator>
    <motor name="left_bogie_front_axle" joint="left_bogie_front_axle" ctrllimited="false" gear="25"/>
    <motor name="left_bogie_rear_axle" joint="left_bogie_rear_axle" ctrllimited="false" gear="25"/>
    <motor name="left_rocker_rear_axle" joint="left_rocker_rear_axle" ctrllimited="false" gear="25"/>
    <motor name="right_bogie_front_axle" joint="right_bogie_front_axle" ctrllimited="false" gear="25"/>
    <motor name="right_bogie_rear_axle" joint="right_bogie_rear_axle" ctrllimited="false" gear="25"/>
    <motor name="right_rocker_rear_axle" joint="right_rocker_rear_axle" ctrllimited="false" gear="25"/>
  </actuator>

  <sensor>
    <actuatorpos name="left_bogie_front_axle_p" actuator="left_bogie_front_axle" />
    <actuatorvel name="left_bogie_front_axle_v" actuator="left_bogie_front_axle" />
    <actuatorpos name="left_bogie_rear_axle_p" actuator="left_bogie_rear_axle" />
    <actuatorvel name="left_bogie_rear_axle_v" actuator="left_bogie_rear_axle" />
    <actuatorpos name="left_rocker_rear_axle_p" actuator="left_rocker_rear_axle" />
    <actuatorvel name="left_rocker_rear_axle_v" actuator="left_rocker_rear_axle" />
    <actuatorpos name="right_bogie_front_axle_p" actuator="right_bogie_front_axle" />
    <actuatorvel name="right_bogie_front_axle_v" actuator="right_bogie_front_axle" />
    <actuatorpos name="right_bogie_rear_axle_p" actuator="right_bogie_rear_axle" />
    <actuatorvel name="right_bogie_rear_axle_v" actuator="right_bogie_rear_axle" />
    <actuatorpos name="right_rocker_rear_axle_p" actuator="right_rocker_rear_axle" />
    <actuatorvel name="right_rocker_rear_axle_v" actuator="right_rocker_rear_axle" />

    <framequat name="orientation" objtype="site" noise="0.001" objname="imu" />
    <gyro name="angular-velocity" site="imu" noise="0.005" cutoff="34.9" />
  </sensor>
</mujoco>
